<?xml version="1.0"?>
<robot name="audition_robot" xmlns:xacro="http://www.ros.org/wiki/xacro">

  <xacro:property name="base_length"  value="0.5"/>
  <xacro:property name="base_width"   value="0.3"/>
  <xacro:property name="base_height"  value="0.15"/>
  <xacro:property name="wheel_radius" value="0.1"/>
  <xacro:property name="wheel_width"  value="0.05"/>
  <xacro:property name="wheel_sep"    value="0.35"/>

  <link name="base_footprint"/>

  <joint name="base_joint" type="fixed">
    <parent link="base_footprint"/>
    <child  link="base_link"/>
    <origin xyz="0 0 ${wheel_radius}" rpy="0 0 0"/>
  </joint>

  <link name="base_link">
    <visual>
      <geometry>
        <box size="${base_length} ${base_width} ${base_height}"/>
      </geometry>
      <material name="blue">
        <color rgba="0.2 0.2 0.8 1.0"/>
      </material>
    </visual>
    <collision>
      <geometry>
        <box size="${base_length} ${base_width} ${base_height}"/>
      </geometry>
    </collision>
    <inertial>
      <mass value="10.0"/>
      <inertia ixx="0.3" ixy="0" ixz="0"
               iyy="0.3" iyz="0"
               izz="0.3"/>
    </inertial>
  </link>

  <xacro:macro name="drive_wheel" params="name x y">
    <link name="${name}_wheel">
      <visual>
        <origin rpy="1.5708 0 0"/>
        <geometry>
          <cylinder radius="${wheel_radius}" length="${wheel_width}"/>
        </geometry>
        <material name="black">
          <color rgba="0.1 0.1 0.1 1.0"/>
        </material>
      </visual>
      <collision>
        <origin rpy="1.5708 0 0"/>
        <geometry>
          <cylinder radius="${wheel_radius}" length="${wheel_width}"/>
        </geometry>
      </collision>
      <inertial>
        <mass value="1.0"/>
        <inertia ixx="0.005" ixy="0" ixz="0"
                 iyy="0.005" iyz="0"
                 izz="0.009"/>
      </inertial>
    </link>
    <joint name="${name}_wheel_joint" type="continuous">
      <parent link="base_link"/>
      <child  link="${name}_wheel"/>
      <origin xyz="${x} ${y} 0" rpy="0 0 0"/>
      <axis xyz="0 1 0"/>
    </joint>
  </xacro:macro>

  <xacro:macro name="caster_wheel" params="name x y">
    <link name="${name}_caster">
      <visual>
        <geometry>
          <sphere radius="${wheel_radius * 0.5}"/>
        </geometry>
        <material name="grey">
          <color rgba="0.5 0.5 0.5 1.0"/>
        </material>
      </visual>
      <collision>
        <geometry>
          <sphere radius="${wheel_radius * 0.5}"/>
        </geometry>
      </collision>
      <inertial>
        <mass value="0.1"/>
        <inertia ixx="0.001" ixy="0" ixz="0"
                 iyy="0.001" iyz="0"
                 izz="0.001"/>
      </inertial>
    </link>
    <joint name="${name}_caster_joint" type="fixed">
      <parent link="base_link"/>
      <child  link="${name}_caster"/>
      <origin xyz="${x} ${y} ${-wheel_radius * 0.5}" rpy="0 0 0"/>
    </joint>
  </xacro:macro>

  <xacro:drive_wheel name="left"  x="0"  y=" ${wheel_sep / 2}"/>
  <xacro:drive_wheel name="right" x="0"  y="-${wheel_sep / 2}"/>

  <xacro:caster_wheel name="front" x=" 0.18" y="0"/>
  <xacro:caster_wheel name="rear"  x="-0.18" y="0"/>

  <link name="laser_link">
    <visual>
      <geometry>
        <cylinder radius="0.05" length="0.04"/>
      </geometry>
      <material name="red">
        <color rgba="0.8 0.1 0.1 1.0"/>
      </material>
    </visual>
  </link>

  <joint name="laser_joint" type="fixed">
    <parent link="base_link"/>
    <child  link="laser_link"/>
    <origin xyz="0.0 0 0.1" rpy="0 0 0"/>
  </joint>

  <!-- camera link -->
  <link name="camera_link">
    <visual>
      <geometry>
        <box size="0.05 0.05 0.05"/>
      </geometry>
      <material name="green">
        <color rgba="0.1 0.8 0.1 1.0"/>
      </material>
    </visual>
  </link>

  <joint name="camera_joint" type="fixed">
    <parent link="base_link"/>
    <child  link="camera_link"/>
    <origin xyz="0.25 0 0.05" rpy="0 0 0"/>
  </joint>

  
  <gazebo>
    <plugin name="differential_drive" filename="libgazebo_ros_diff_drive.so">
      <left_joint>left_wheel_joint</left_joint>
      <right_joint>right_wheel_joint</right_joint>
      <wheel_separation>${wheel_sep}</wheel_separation>
      <wheel_diameter>${wheel_radius * 2}</wheel_diameter>
      <max_wheel_torque>100</max_wheel_torque>
      <max_wheel_acceleration>5.0</max_wheel_acceleration>
      <command_topic>cmd_vel</command_topic>
      <odometry_topic>odom</odometry_topic>
      <odometry_frame>odom</odometry_frame>
      <robot_base_frame>base_footprint</robot_base_frame>
      <publish_odom>true</publish_odom>
      <publish_odom_tf>true</publish_odom_tf>
      <publish_wheel_tf>false</publish_wheel_tf>
      <update_rate>30</update_rate>
    </plugin>
  </gazebo>

  
  <gazebo reference="left_wheel">
    <mu1>2.0</mu1>
    <mu2>2.0</mu2>
    <kp>1000000.0</kp>
    <kd>1.0</kd>
  </gazebo>

  <gazebo reference="right_wheel">
    <mu1>2.0</mu1>
    <mu2>2.0</mu2>
    <kp>1000000.0</kp>
    <kd>1.0</kd>
  </gazebo>

  <gazebo reference="front_caster">
    <mu1>0.0</mu1>
    <mu2>0.0</mu2>
    <kp>1000000.0</kp>
    <kd>1.0</kd>
  </gazebo>

  <gazebo reference="rear_caster">
    <mu1>0.0</mu1>
    <mu2>0.0</mu2>
    <kp>1000000.0</kp>
    <kd>1.0</kd>
  </gazebo>

  <gazebo reference="laser_link">
    <sensor name="lidar" type="ray">
      <always_on>true</always_on>
      <visualize>true</visualize>
      <update_rate>10</update_rate>
      <ray>
        <scan>
          <horizontal>
            <samples>360</samples>
            <resolution>1</resolution>
            <min_angle>-3.14159</min_angle>
            <max_angle>3.14159</max_angle>
          </horizontal>
        </scan>
        <range>
          <min>0.1</min>
          <max>10.0</max>
          <resolution>0.01</resolution>
        </range>
      </ray>
      <plugin name="lidar_plugin" filename="libgazebo_ros_ray_sensor.so">
        <ros>
          <remapping>~/out:=scan</remapping>
        </ros>
        <output_type>sensor_msgs/LaserScan</output_type>
        <frame_name>laser_link</frame_name>
      </plugin>
    </sensor>
  </gazebo>

  
  <gazebo reference="camera_link">
    <sensor name="depth_camera" type="depth">
      <always_on>true</always_on>
      <update_rate>15</update_rate>
      <camera>
        <horizontal_fov>1.047</horizontal_fov>
        <image>
          <width>640</width>
          <height>480</height>
          <format>R8G8B8</format>
        </image>
        <clip>
          <near>0.1</near>
          <far>10.0</far>
        </clip>
      </camera>
      <plugin name="depth_camera_plugin" filename="libgazebo_ros_camera.so">
        <frame_name>camera_link</frame_name>
        <min_depth>0.1</min_depth>
        <max_depth>10.0</max_depth>
      </plugin>
    </sensor>
  </gazebo>

</robot>
